Workbook

Sheet Sheet1
H2: 개별 생산 내역 TREND
S4: 2022.01 | W4: 2022.02 | AA4: 2022.03 | AE4: 2022.04 | AI4: 2022.05 | AM4: 2022.06 | AQ4: 2022.07 | AU4: 2022.08 | AY4: 2022.09 | BC4: 2022.10 | BG4: 2022.11 | BK4: 2022.12 | BO4: 2023.01 | BS4: 2023.02
E5: 모규격 | F5: 모규격 | G5: 모품번 | H5: 모품명 | K5: 모단위 | L5: 생산수량 | M5: 단위재료비 | N5: 재료비 | O5: 자품번 | P5: 품번 | Q5: 구분 | R5: 자품명 | S5: 비중 | T5: 사용량 | U5: 사용단가 | V5: 사용금액 | W5: 비중 | X5: 사용량 | Y5: 사용단가 | Z5: 사용금액 | AA5: 비중 | AB5: 사용량 | AC5: 사용단가 | AD5: 사용금액 | AE5: 비중 | AF5: 사용량 | AG5: 사용단가 | AH5: 사용금액 | AI5: 비중 | AJ5: 사용량 | AK5: 사용단가 | AL5: 사용금액 | AM5: 비중 | AN5: 사용량 | AO5: 사용단가 | AP5: 사용금액 | AQ5: 비중 | AR5: 사용량 | AS5: 사용단가 | AT5: 사용금액 | AU5: 비중 | AV5: 사용량 | AW5: 사용단가 | AX5: 사용금액 | AY5: 비중 | AZ5: 사용량 | BA5: 사용단가 | BB5: 사용금액 | BC5: 비중 | BD5: 사용량 | BE5: 사용단가 | BF5: 사용금액 | BG5: 비중 | BH5: 사용량 | BI5: 사용단가 | BJ5: 사용금액 | BK5: 비중 | BL5: 사용량 | BM5: 사용단가 | BN5: 사용금액 | BO5: 비중 | BP5: 사용량 | BQ5: 사용단가 | BR5: 사용금액 | BS5: 비중 | BT5: 사용량 | BU5: 사용단가 | BV5: 사용금액
B6: =CONCATENATE(E6,O6) -> #REF! | C6: =CONCATENATE(E6,R6) -> #REF! | D6: =CONCATENATE(E6,R6) -> #REF! | E6: =IF(G6=0,#REF!,G6) -> #REF! | F6: =IF(#REF!=0,#REF!,#REF!) -> #REF! | H6: TPAA103 | I6: TPAA103 | K6: KG | L6: 43370 | M6: 2776.41 | N6: 120412944 | O6: 3402104 | P6: =+O6*1 -> 3402104 | Q6: =VLOOKUP(P6,[1]A!D:G,3,FALSE) -> 0 | R6: MPPO JM-594L | S6: 0 | T6: 0 | U6: 0 | V6: 0 | W6: 0 | X6: 0 | Y6: 0 | Z6: 0 | AA6: 0 | AB6: 0 | AC6: 0 | AD6: 0 | AE6: 0 | AF6: 0 | AG6: 0 | AH6: 0 | AI6: 0 | AJ6: 0 | AK6: 0 | AL6: 0 | AM6: 0 | AN6: 0 | AO6: 0 | AP6: 0 | AQ6: 0 | AR6: 0 | AS6: 0 | AT6: 0 | AU6: 0 | AV6: 0 | AW6: 0 | AX6: 0 | AY6: 0 | AZ6: 0 | BA6: 0 | BB6: 0 | BC6: 0 | BD6: 0 | BE6: 0 | BF6: 0 | BG6: 0 | BH6: 0 | BI6: 0 | BJ6: 0 | BK6: 0 | BL6: 0 | BM6: 0 | BN6: 0 | BO6: 0 | BP6: 0 | BQ6: 0 | BR6: 0 | BS6: 0 | BT6: 0 | BU6: 0 | BV6: 0
B7: =CONCATENATE(E7,O7) -> #REF! | C7: =CONCATENATE(E7,R7) -> #REF! | D7: =CONCATENATE(E7,R7) -> #REF! | E7: =IF(G7=0,E6,G7) -> #REF! | F7: =IF(H7=0,F6,H7) -> #REF! | I7: TPAA103 | O7: 3402105 | P7: =+O7*1 -> 3402105 | Q7: =VLOOKUP(P7,[1]A!D:G,3,FALSE) -> MPPO | R7: MPPO JM-595M | S7: 0.150656 | T7: 29900 | U7: 3452.8 | V7: 103238796 | W7: 0.148248 | X7: 6800 | Y7: 3562.23 | Z7: 24223175 | AA7: 0.148492 | AB7: 33100 | AC7: 3725.687 | AD7: 123320239 | AE7: 0 | AF7: 0 | AG7: 0 | AH7: 0 | AI7: 0.151561 | AJ7: 5000 | AK7: 3664.4982 | AL7: 18322491 | AM7: 0.1566 | AN7: 11750 | AO7: 3755.8892 | AP7: 44131698 | AQ7: 0.156092 | AR7: 7100 | AS7: 3969.5163 | AT7: 28183566 | AU7: 0.155089 | AV7: 9500 | AW7: 4058.344 | AX7: 38554268 | AY7: 0.153695 | AZ7: 3825 | BA7: 4115.8366 | BB7: 15743075 | BC7: 0.155067 | BD7: 8150 | BE7: 4129.8733 | BF7: 33658467 | BG7: 0 | BH7: 0 | BI7: 0 | BJ7: 0 | BK7: 0.153932 | BL7: 9525 | BM7: 4220.5815 | BN7: 40201039 | BO7: 0.153408 | BP7: 12400 | BQ7: 4220.5815 | BR7: 52335211 | BS7: 0.15324 | BT7: 20700 | BU7: 3948.172 | BV7: 81727161
C8: =CONCATENATE(E8,R8) -> #REF! | E8: =IF(G8=0,E7,G8) -> #REF! | I8: TPAA103 | Q8: =VLOOKUP(P8,[1]A!D:G,3,FALSE) -> 0 | R8: =+Q7 -> MPPO | S8: 0.150656 | T8: 29900 | U8: 3452.8025 | V8: 103238796 | W8: 0.148248 | X8: 6800 | Y8: 3562.2316 | Z8: 24223175 | AA8: 0.148492 | AB8: 33100 | AC8: 3725.687 | AD8: 123320239 | AE8: 0 | AF8: 0 | AG8: 0 | AH8: 0 | AI8: 0.151561 | AJ8: 5000 | AK8: 3664.4982 | AL8: 18322491 | AM8: 0.1566 | AN8: 11750 | AO8: 3755.8892 | AP8: 44131698 | AQ8: 0.156092 | AR8: 7100 | AS8: 3969.5163 | AT8: 28183566 | AU8: 0.155089 | AV8: 9500 | AW8: 4058.344 | AX8: 38554268 | AY8: 0.153695 | AZ8: 3825 | BA8: 4115.8366 | BB8: 15743075 | BC8: 0.155067 | BD8: 8150 | BE8: 4129.8733 | BF8: 33658467 | BG8: 0 | BH8: 0 | BI8: 0 | BJ8: 0 | BK8: 0.153932 | BL8: 9525 | BM8: 4220.5815 | BN8: 40201039 | BO8: 0.153408 | BP8: 12400 | BQ8: 4220.5815 | BR8: 52335211 | BS8: 0.15324 | BT8: 20700 | BU8: 3948.172 | BV8: 81727161
B9: =CONCATENATE(E9,O9) -> #REF! | C9: =CONCATENATE(E9,R9) -> #REF! | D9: =CONCATENATE(E9,R9) -> #REF! | E9: =IF(G9=0,E7,G9) -> #REF! | F9: =IF(H9=0,F6,H9) -> #REF! | I9: TPAA103 | O9: 3403301 | P9: =+O9*1 -> 3403301 | Q9: =VLOOKUP(P9,[1]A!D:G,3,FALSE) -> #N/A | R9: MPPO<C> | S9: 0 | T9: 0 | U9: 0 | V9: 0 | W9: 0 | X9: 0 | Y9: 0 | Z9: 0 | AA9: 0 | AB9: 0 | AC9: 0 | AD9: 0 | AE9: 0 | AF9: 0 | AG9: 0 | AH9: 0 | AI9: 0 | AJ9: 0 | AK9: 0 | AL9: 0 | AM9: 0 | AN9: 0 | AO9: 0 | AP9: 0 | AQ9: 0 | AR9: 0 | AS9: 0 | AT9: 0 | AU9: 0 | AV9: 0 | AW9: 0 | AX9: 0 | AY9: 0 | AZ9: 0 | BA9: 0 | BB9: 0 | BC9: 0 | BD9: 0 | BE9: 0 | BF9: 0 | BG9: 0 | BH9: 0 | BI9: 0 | BJ9: 0 | BK9: 0 | BL9: 0 | BM9: 0 | BN9: 0 | BO9: 0 | BP9: 0 | BQ9: 0 | BR9: 0 | BS9: 0 | BT9: 0 | BU9: 0 | BV9: 0
B10: =CONCATENATE(E10,O10) -> #REF! | C10: =CONCATENATE(E10,R10) -> #REF! | D10: =CONCATENATE(E10,R10) -> #REF! | E10: =IF(G10=0,E9,G10) -> #REF! | F10: =IF(H10=0,F9,H10) -> #REF! | I10: TPAA103 | O10: 3403303 | P10: =+O10*1 -> 3403303 | Q10: =VLOOKUP(P10,[1]A!D:G,3,FALSE) -> R재 | R10: MPPO<K> | S10: 0.338977 | T10: 67275 | U10: 1853.24 | V10: 124676681 | W10: 0.399834 | X10: 18340 | Y10: 1945.73 | Z10: 35684754 | AA10: 0.40891 | AB10: 91149 | AC10: 1971.1022 | AD10: 179663997 | AE10: 0 | AF10: 0 | AG10: 0 | AH10: 0 | AI10: 0.491058 | AJ10: 16200 | AK10: 2036.607 | AL10: 32993033 | AM10: 0.505118 | AN10: 37900 | AO10: 2067.1551 | AP10: 78345178 | AQ10: 0.507299 | AR10: 23075 | AS10: 2074.1618 | AT10: 47861284 | AU10: 0.50404 | AV10: 30875 | AW10: 2079.5406 | AX10: 64205815 | AY10: 0.498252 | AZ10: 12400 | BA10: 2104.1223 | BB10: 26091117 | BC10: 0.503254 | BD10: 26450 | BE10: 2118.7192 | BF10: 56040122 | BG10: 0 | BH10: 0 | BI10: 0 | BJ10: 0 | BK10: 0.49937 | BL10: 30900 | BM10: 1931.0718 | BN10: 59670120 | BO10: 0.497959 | BP10: 40250 | BQ10: 1887.6868 | BR10: 75979392 | BS10: 0.498401 | BT10: 67325 | BU10: 1870.0103 | BV10: 125898445
B11: =CONCATENATE(E11,O11) -> #REF! | C11: =CONCATENATE(E11,R11) -> #REF! | D11: =CONCATENATE(E11,R11) -> #REF! | E11: =IF(G11=0,E10,G11) -> #REF! | F11: =IF(H11=0,F10,H11) -> #REF! | I11: TPAA103 | O11: 3403305 | P11: =+O11*1 -> 3403305 | Q11: =VLOOKUP(P11,[1]A!D:G,3,FALSE) -> R재 | R11: MPPO<S> | S11: 0.129998 | T11: 25800 | U11: 1946.62 | V11: 50222921 | W11: 0 | X11: 0 | Y11: 0 | Z11: 0 | AA11: 0 | AB11: 0 | AC11: 0 | AD11: 0 | AE11: 0 | AF11: 0 | AG11: 0 | AH11: 0 | AI11: 0 | AJ11: 0 | AK11: 0 | AL11: 0 | AM11: 0 | AN11: 0 | AO11: 0 | AP11: 0 | AQ11: 0 | AR11: 0 | AS11: 0 | AT11: 0 | AU11: 0 | AV11: 0 | AW11: 0 | AX11: 0 | AY11: 0 | AZ11: 0 | BA11: 0 | BB11: 0 | BC11: 0 | BD11: 0 | BE11: 0 | BF11: 0 | BG11: 0 | BH11: 0 | BI11: 0 | BJ11: 0 | BK11: 0 | BL11: 0 | BM11: 0 | BN11: 0 | BO11: 0 | BP11: 0 | BQ11: 0 | BR11: 0 | BS11: 0 | BT11: 0 | BU11: 0 | BV11: 0
B12: =CONCATENATE(E12,O12) -> #REF! | C12: =CONCATENATE(E12,R12) -> #REF! | D12: =CONCATENATE(E12,R12) -> #REF! | E12: =IF(G12=0,E11,G12) -> #REF! | F12: =IF(H12=0,F11,H12) -> #REF! | I12: TPAA103 | O12: 3403309 | P12: =+O12*1 -> 3403309 | Q12: =VLOOKUP(P12,[1]A!D:G,3,FALSE) -> R재 | R12: MPPO<EK> | S12: 0 | T12: 0 | U12: 0 | V12: 0 | W12: 0.013081 | X12: 600 | Y12: 1860.34 | Z12: 1116204 | AA12: 0 | AB12: 0 | AC12: 0 | AD12: 0 | AE12: 0 | AF12: 0 | AG12: 0 | AH12: 0 | AI12: 0 | AJ12: 0 | AK12: 0 | AL12: 0 | AM12: 0 | AN12: 0 | AO12: 0 | AP12: 0 | AQ12: 0 | AR12: 0 | AS12: 0 | AT12: 0 | AU12: 0 | AV12: 0 | AW12: 0 | AX12: 0 | AY12: 0 | AZ12: 0 | BA12: 0 | BB12: 0 | BC12: 0 | BD12: 0 | BE12: 0 | BF12: 0 | BG12: 0 | BH12: 0 | BI12: 0 | BJ12: 0 | BK12: 0 | BL12: 0 | BM12: 0 | BN12: 0 | BO12: 0 | BP12: 0 | BQ12: 0 | BR12: 0 | BS12: 0 | BT12: 0 | BU12: 0 | BV12: 0
B13: =CONCATENATE(E13,O13) -> #REF! | C13: =CONCATENATE(E13,R13) -> #REF! | D13: =CONCATENATE(E13,R13) -> #REF! | E13: =IF(G13=0,E12,G13) -> #REF! | F13: =IF(H13=0,F12,H13) -> #REF! | I13: TPAA103 | O13: 3403311 | P13: =+O13*1 -> 3403311 | Q13: =VLOOKUP(P13,[1]A!D:G,3,FALSE) -> R재 | R13: MPPO<DW> | S13: 0 | T13: 0 | U13: 0 | V13: 0 | W13: 0 | X13: 0 | Y13: 0 | Z13: 0 | AA13: 0 | AB13: 0 | AC13: 0 | AD13: 0 | AE13: 0 | AF13: 0 | AG13: 0 | AH13: 0 | AI13: 0 | AJ13: 0 | AK13: 0 | AL13: 0 | AM13: 0 | AN13: 0 | AO13: 0 | AP13: 0 | AQ13: 0 | AR13: 0 | AS13: 0 | AT13: 0 | AU13: 0 | AV13: 0 | AW13: 0 | AX13: 0 | AY13: 0 | AZ13: 0 | BA13: 0 | BB13: 0 | BC13: 0 | BD13: 0 | BE13: 0 | BF13: 0 | BG13: 0 | BH13: 0 | BI13: 0 | BJ13: 0 | BK13: 0 | BL13: 0 | BM13: 0 | BN13: 0 | BO13: 0 | BP13: 0 | BQ13: 0 | BR13: 0 | BS13: 0 | BT13: 0 | BU13: 0 | BV13: 0
B14: =CONCATENATE(E14,O14) -> #REF! | C14: =CONCATENATE(E14,R14) -> #REF! | D14: =CONCATENATE(E14,R14) -> #REF! | E14: =IF(G14=0,E13,G14) -> #REF! | F14: =IF(H14=0,F13,H14) -> #REF! | I14: TPAA103 | O14: 3403323 | P14: =+O14*1 -> 3403323 | Q14: =VLOOKUP(P14,[1]A!D:G,3,FALSE) -> R재 | R14: MPPO<PK> | W14: 0.112276 | X14: 5150 | Y14: 1460 | Z14: 7519000 | AA14: 0.111369 | AB14: 24825 | AC14: 1460 | AD14: 36244500 | AE14: 0 | AF14: 0 | AG14: 0 | AH14: 0 | AI14: 0 | AJ14: 0 | AK14: 0 | AL14: 0 | AM14: 0 | AN14: 0 | AO14: 0 | AP14: 0 | AQ14: 0 | AR14: 0 | AS14: 0 | AT14: 0 | AU14: 0 | AV14: 0 | AW14: 0 | AX14: 0 | AY14: 0 | AZ14: 0 | BA14: 0 | BB14: 0 | BC14: 0 | BD14: 0 | BE14: 0 | BF14: 0 | BG14: 0 | BH14: 0 | BI14: 0 | BJ14: 0 | BK14: 0 | BL14: 0 | BM14: 0 | BN14: 0
B15: =CONCATENATE(E15,O15) -> #REF! | C15: =CONCATENATE(E15,R15) -> #REF! | D15: =CONCATENATE(E15,R15) -> #REF! | E15: =IF(G15=0,E12,G15) -> #REF! | F15: =IF(H15=0,F12,H15) -> #REF! | I15: TPAA103 | O15: 3404303 | P15: =+O15*1 -> 3404303 | Q15: =VLOOKUP(P15,[1]A!D:G,3,FALSE) -> R재 | R15: MPSU(B) | S15: 0 | T15: 0 | U15: 0 | V15: 0 | W15: 0 | X15: 0 | Y15: 0 | Z15: 0 | AA15: 0 | AB15: 0 | AC15: 0 | AD15: 0 | AE15: 0 | AF15: 0 | AG15: 0 | AH15: 0 | AI15: 0 | AJ15: 0 | AK15: 0 | AL15: 0 | AM15: 0 | AN15: 0 | AO15: 0 | AP15: 0 | AQ15: 0 | AR15: 0 | AS15: 0 | AT15: 0 | AU15: 0 | AV15: 0 | AW15: 0 | AX15: 0 | AY15: 0 | AZ15: 0 | BA15: 0 | BB15: 0 | BC15: 0 | BD15: 0 | BE15: 0 | BF15: 0 | BG15: 0 | BH15: 0 | BI15: 0 | BJ15: 0 | BK15: 0 | BL15: 0 | BM15: 0 | BN15: 0 | BO15: 0 | BP15: 0 | BQ15: 0 | BR15: 0 | BS15: 0 | BT15: 0 | BU15: 0 | BV15: 0
B16: =CONCATENATE(E16,O16) -> #REF! | C16: =CONCATENATE(E16,R16) -> #REF! | D16: =CONCATENATE(E16,R16) -> #REF! | E16: =IF(G16=0,E13,G16) -> #REF! | F16: =IF(H16=0,F13,H16) -> #REF! | I16: TPAA103 | O16: 3403313 | P16: =+O16*1 -> 3403313 | Q16: =VLOOKUP(P16,[1]A!D:G,3,FALSE) -> R재 | R16: MPPO<GF-A> | S16: 0.17333 | T16: 34400 | U16: 1787.69 | V16: 61496495 | W16: 0.112276 | X16: 5150 | Y16: 1819 | Z16: 9367830 | AA16: 0.111369 | AB16: 24825 | AC16: 1829.5663 | AD16: 45418984 | AE16: 0 | AF16: 0 | AG16: 0 | AH16: 0 | AI16: 0.151561 | AJ16: 5000 | AK16: 1876.8418 | AL16: 9384209 | AM16: 0.155933 | AN16: 11700 | AO16: 1879.5079 | AP16: 21990243 | AQ16: 0.156092 | AR16: 7100 | AS16: 1880.1084 | AT16: 13348770 | AU16: 0.155498 | AV16: 9525 | AW16: 1880.1085 | AX16: 17908033 | AY16: 0.153695 | AZ16: 3825 | BA16: 1879.3156 | BB16: 7188382 | BC16: 0.155067 | BD16: 8150 | BE16: 1926.4492 | BF16: 15700561 | BG16: 0 | BH16: 0 | BI16: 0 | BJ16: 0 | BK16: 0.153932 | BL16: 9525 | BM16: 1743.1858 | BN16: 16603845 | BO16: 0.153408 | BP16: 12400 | BQ16: 1667.8819 | BR16: 20681735 | BS16: 0.15361 | BT16: 20750 | BU16: 1656.7833 | BV16: 34378254
C17: =CONCATENATE(E17,R17) -> #REF! | E17: =IF(G17=0,E16,G17) -> #REF! | I17: TPAA103 | Q17: =VLOOKUP(P17,[1]A!D:G,3,FALSE) -> 0 | R17: =+Q16 -> R재 | S17: 0.642305 | T17: 127475 | U17: 1854.4507 | V17: 236396097 | W17: 0.637467 | X17: 29240 | Y17: 1836.1077 | Z17: 53687788 | AA17: 0.631648 | AB17: 140799 | AC17: 1856.0322 | AD17: 261327481 | AE17: 0 | AF17: 0 | AG17: 0 | AH17: 0 | AI17: 0.642619 | AJ17: 21200 | AK17: 1998.9265 | AL17: 42377242 | AM17: 0.661051 | AN17: 49600 | AO17: 2022.8916 | AP17: 100335421 | AQ17: 0.663391 | AR17: 30175 | AS17: 2028.5022 | AT17: 61210054 | AU17: 0.659538 | AV17: 40400 | AW17: 2032.521 | AX17: 82113848 | AY17: 0.651947 | AZ17: 16225 | BA17: 2051.1247 | BB17: 33279499 | BC17: 0.658321 | BD17: 34600 | BE17: 2073.4301 | BF17: 71740683 | BG17: 0 | BH17: 0 | BI17: 0 | BJ17: 0 | BK17: 0.653302 | BL17: 40425 | BM17: 1886.8019 | BN17: 76273965 | BO17: 0.651367 | BP17: 52650 | BQ17: 1835.9188 | BR17: 96661127 | BS17: 0.652011 | BT17: 88075 | BU17: 1819.7752 | BV17: 160276699
B18: =CONCATENATE(E18,O18) -> #REF! | C18: =CONCATENATE(E18,R18) -> #REF! | D18: =CONCATENATE(E18,R18) -> #REF! | E18: =IF(G18=0,E17,G18) -> #REF! | F18: =IF(H18=0,F10,H18) -> #REF! | I18: TPAA103 | O18: 3414085 | P18: =+O18*1 -> 3414085 | Q18: =VLOOKUP(P18,[1]A!D:G,3,FALSE) -> SEBS | R18: YJ-5085AN | S18: 0 | T18: 0 | U18: 0 | V18: 0 | W18: 0 | X18: 0 | Y18: 0 | Z18: 0 | AA18: 0 | AB18: 0 | AC18: 0 | AD18: 0 | AE18: 0 | AF18: 0 | AG18: 0 | AH18: 0 | AI18: 0 | AJ18: 0 | AK18: 0 | AL18: 0 | AM18: 0 | AN18: 0 | AO18: 0 | AP18: 0 | AQ18: 0 | AR18: 0 | AS18: 0 | AT18: 0 | AU18: 0 | AV18: 0 | AW18: 0 | AX18: 0 | AY18: 0 | AZ18: 0 | BA18: 0 | BB18: 0 | BC18: 0 | BD18: 0 | BE18: 0 | BF18: 0 | BG18: 0 | BH18: 0 | BI18: 0 | BJ18: 0 | BK18: 0 | BL18: 0 | BM18: 0 | BN18: 0 | BO18: 0 | BP18: 0 | BQ18: 0 | BR18: 0 | BS18: 0 | BT18: 0 | BU18: 0 | BV18: 0
B19: =CONCATENATE(E19,O19) -> #REF! | C19: =CONCATENATE(E19,R19) -> #REF! | D19: =CONCATENATE(E19,R19) -> #REF! | E19: =IF(G19=0,E18,G19) -> #REF! | F19: =IF(H19=0,F11,H19) -> #REF! | I19: TPAA103 | O19: 3414086 | P19: =+O19*1 -> 3414086 | Q19: =VLOOKUP(P19,[1]A!D:G,3,FALSE) -> SEBS | R19: YJ-5085AKG | S19: 0.037664 | T19: 7475 | U19: 4200 | V19: 31395000 | W19: 0.03837 | X19: 1760 | Y19: 4200 | Z19: 7392000 | AA19: 0.037123 | AB19: 8275 | AC19: 4084.6247 | AD19: 33800269 | AE19: 0 | AF19: 0 | AG19: 0 | AH19: 0 | AI19: 0.037132 | AJ19: 1225 | AK19: 4210.6245 | AL19: 5158015 | AM19: 0.038983 | AN19: 2925 | AO19: 4251.8574 | AP19: 12436683 | AQ19: 0.039023 | AR19: 1775 | AS19: 4251.8575 | AT19: 7547047 | AU19: 0.038772 | AV19: 2375 | AW19: 4251.8577 | AX19: 10098162 | AY19: 0.038173 | AZ19: 950 | BA19: 4250.5505 | BB19: 4038023 | BC19: 0.038529 | BD19: 2025 | BE19: 4250.5501 | BF19: 8607364 | BG19: 0 | BH19: 0 | BI19: 0 | BJ19: 0 | BK19: 0.038786 | BL19: 2400 | BM19: 4547.7604 | BN19: 10914625 | BO19: 0.038352 | BP19: 3100 | BQ19: 4596.61 | BR19: 14249491 | BS19: 0.03831 | BT19: 5175 | BU19: 4390.9561 | BV19: 22723198
C20: =CONCATENATE(E20,R20) -> #REF! | E20: =IF(G20=0,E19,G20) -> #REF! | I20: TPAA103 | Q20: =VLOOKUP(P20,[1]A!D:G,3,FALSE) -> 0 | R20: =+Q19 -> SEBS | S20: 0.037664 | T20: 7475 | U20: 4200 | V20: 31395000 | W20: 0.03837 | X20: 1760 | Y20: 4200 | Z20: 7392000 | AA20: 0.037123 | AB20: 8275 | AC20: 4084.6247 | AD20: 33800269 | AE20: 0 | AF20: 0 | AG20: 0 | AH20: 0 | AI20: 0.037132 | AJ20: 1225 | AK20: 4210.6245 | AL20: 5158015 | AM20: 0.038983 | AN20: 2925 | AO20: 4251.8574 | AP20: 12436683 | AQ20: 0.039023 | AR20: 1775 | AS20: 4251.8575 | AT20: 7547047 | AU20: 0.038772 | AV20: 2375 | AW20: 4251.8577 | AX20: 10098162 | AY20: 0.038173 | AZ20: 950 | BA20: 4250.5505 | BB20: 4038023 | BC20: 0.038529 | BD20: 2025 | BE20: 4250.5501 | BF20: 8607364 | BG20: 0 | BH20: 0 | BI20: 0 | BJ20: 0 | BK20: 0.038786 | BL20: 2400 | BM20: 4547.7604 | BN20: 10914625 | BO20: 0.038352 | BP20: 3100 | BQ20: 4596.61 | BR20: 14249491 | BS20: 0.03831 | BT20: 5175 | BU20: 4390.9561 | BV20: 22723198
B21: =CONCATENATE(E21,O21) -> #REF! | C21: =CONCATENATE(E21,R21) -> #REF! | D21: =CONCATENATE(E21,R21) -> #REF! | E21: =IF(G21=0,E18,G21) -> #REF! | F21: =IF(H21=0,F11,H21) -> #REF! | I21: TPAA103 | O21: 3457002 | P21: =+O21*1 -> 3457002 | Q21: =VLOOKUP(P21,[1]A!D:G,3,FALSE) -> 0 | R21: C/F S-75(YJC-205) | S21: 0 | T21: 0 | U21: 0 | V21: 0 | W21: 0 | X21: 0 | Y21: 0 | Z21: 0 | AA21: 0 | AB21: 0 | AC21: 0 | AD21: 0 | AE21: 0 | AF21: 0 | AG21: 0 | AH21: 0 | AI21: 0 | AJ21: 0 | AK21: 0 | AL21: 0 | AM21: 0 | AN21: 0 | AO21: 0 | AP21: 0 | AQ21: 0 | AR21: 0 | AS21: 0 | AT21: 0 | AU21: 0 | AV21: 0 | AW21: 0 | AX21: 0 | AY21: 0 | AZ21: 0 | BA21: 0 | BB21: 0 | BC21: 0 | BD21: 0 | BE21: 0 | BF21: 0 | BG21: 0 | BH21: 0 | BI21: 0 | BJ21: 0 | BK21: 0 | BL21: 0 | BM21: 0 | BN21: 0 | BO21: 0 | BP21: 0 | BQ21: 0 | BR21: 0 | BS21: 0 | BT21: 0 | BU21: 0 | BV21: 0
B22: =CONCATENATE(E22,O22) -> #REF! | C22: =CONCATENATE(E22,R22) -> #REF! | D22: =CONCATENATE(E22,R22) -> #REF! | E22: =IF(G22=0,E21,G22) -> #REF! | F22: =IF(H22=0,F12,H22) -> #REF! | I22: TPAA103 | O22: 3457011 | P22: =+O22*1 -> 3457011 | Q22: =VLOOKUP(P22,[1]A!D:G,3,FALSE) -> 0 | R22: ACECA-6PU | S22: 0 | T22: 0 | U22: 0 | V22: 0 | W22: 0 | X22: 0 | Y22: 0 | Z22: 0 | AA22: 0 | AB22: 0 | AC22: 0 | AD22: 0 | AE22: 0 | AF22: 0 | AG22: 0 | AH22: 0 | AI22: 0 | AJ22: 0 | AK22: 0 | AL22: 0 | AM22: 0 | AN22: 0 | AO22: 0 | AP22: 0 | AQ22: 0 | AR22: 0 | AS22: 0 | AT22: 0 | AU22: 0 | AV22: 0 | AW22: 0 | AX22: 0 | AY22: 0 | AZ22: 0 | BA22: 0 | BB22: 0 | BC22: 0 | BD22: 0 | BE22: 0 | BF22: 0 | BG22: 0 | BH22: 0 | BI22: 0 | BJ22: 0 | BK22: 0 | BL22: 0 | BM22: 0 | BN22: 0 | BO22: 0 | BP22: 0 | BQ22: 0 | BR22: 0 | BS22: 0 | BT22: 0 | BU22: 0 | BV22: 0
B23: =CONCATENATE(E23,O23) -> #REF! | C23: =CONCATENATE(E23,R23) -> #REF! | D23: =CONCATENATE(E23,R23) -> #REF! | E23: =IF(G23=0,E22,G23) -> #REF! | F23: =IF(H23=0,F13,H23) -> #REF! | I23: TPAA103 | O23: 3457015 | P23: =+O23*1 -> 3457015 | Q23: =VLOOKUP(P23,[1]A!D:G,3,FALSE) -> C/F | R23: RCA(ZOLTEK) | S23: 0.000267 | T23: 53 | U23: 13778.98 | V23: 730286 | W23: 0.04805 | X23: 2204 | Y23: 14373.57 | Z23: 31679348 | AA23: 0.050474 | AB23: 11251 | AC23: 14782.044 | AD23: 166312782 | AE23: 0 | AF23: 0 | AG23: 0 | AH23: 0 | AI23: 0 | AJ23: 0 | AK23: 0 | AL23: 0 | AM23: 0 | AN23: 0 | AO23: 0 | AP23: 0 | AQ23: 0 | AR23: 0 | AS23: 0 | AT23: 0 | AU23: 0 | AV23: 0 | AW23: 0 | AX23: 0 | AY23: 0 | AZ23: 0 | BA23: 0 | BB23: 0 | BC23: 0 | BD23: 0 | BE23: 0 | BF23: 0 | BG23: 0 | BH23: 0 | BI23: 0 | BJ23: 0 | BK23: 0.011636 | BL23: 720 | BM23: 15959.9 | BN23: 11491128 | BO23: 0 | BP23: 0 | BQ23: 0 | BR23: 0 | BS23: 0 | BT23: 0 | BU23: 0 | BV23: 0
B24: =CONCATENATE(E24,O24) -> #REF! | C24: =CONCATENATE(E24,R24) -> #REF! | D24: =CONCATENATE(E24,R24) -> #REF! | E24: =IF(G24=0,E23,G24) -> #REF! | F24: =IF(H24=0,F16,H24) -> #REF! | I24: TPAA103 | O24: 3457017 | P24: =+O24*1 -> 3457017 | Q24: =VLOOKUP(P24,[1]A!D:G,3,FALSE) -> 0 | R24: C/F DIC(201) | S24: 0 | T24: 0 | U24: 0 | V24: 0 | W24: 0 | X24: 0 | Y24: 0 | Z24: 0 | AA24: 0 | AB24: 0 | AC24: 0 | AD24: 0 | AE24: 0 | AF24: 0 | AG24: 0 | AH24: 0 | AI24: 0 | AJ24: 0 | AK24: 0 | AL24: 0 | AM24: 0 | AN24: 0 | AO24: 0 | AP24: 0 | AQ24: 0 | AR24: 0 | AS24: 0 | AT24: 0 | AU24: 0 | AV24: 0 | AW24: 0 | AX24: 0 | AY24: 0 | AZ24: 0 | BA24: 0 | BB24: 0 | BC24: 0 | BD24: 0 | BE24: 0 | BF24: 0 | BG24: 0 | BH24: 0 | BI24: 0 | BJ24: 0 | BK24: 0 | BL24: 0 | BM24: 0 | BN24: 0 | BO24: 0 | BP24: 0 | BQ24: 0 | BR24: 0 | BS24: 0 | BT24: 0 | BU24: 0 | BV24: 0
B25: =CONCATENATE(E25,O25) -> #REF! | C25: =CONCATENATE(E25,R25) -> #REF! | D25: =CONCATENATE(E25,R25) -> #REF! | E25: =IF(G25=0,E24,G25) -> #REF! | F25: =IF(H25=0,F18,H25) -> #REF! | I25: TPAA103 | O25: 3457031 | P25: =+O25*1 -> 3457031 | Q25: =VLOOKUP(P25,[1]A!D:G,3,FALSE) -> C/F | R25: C/F CT+SM45D-06-50 | S25: 0 | T25: 0 | U25: 0 | V25: 0 | W25: 0 | X25: 0 | Y25: 0 | Z25: 0 | AA25: 0 | AB25: 0 | AC25: 0 | AD25: 0 | AE25: 0 | AF25: 0 | AG25: 0 | AH25: 0 | AI25: 0 | AJ25: 0 | AK25: 0 | AL25: 0 | AM25: 0 | AN25: 0 | AO25: 0 | AP25: 0 | AQ25: 0 | AR25: 0 | AS25: 0 | AT25: 0 | AU25: 0 | AV25: 0 | AW25: 0 | AX25: 0 | AY25: 0 | AZ25: 0 | BA25: 0 | BB25: 0 | BC25: 0 | BD25: 0 | BE25: 0 | BF25: 0 | BG25: 0 | BH25: 0 | BI25: 0 | BJ25: 0 | BK25: 0 | BL25: 0 | BM25: 0 | BN25: 0 | BO25: 0 | BP25: 0 | BQ25: 0 | BR25: 0 | BS25: 0 | BT25: 0 | BU25: 0 | BV25: 0
B26: =CONCATENATE(E26,O26) -> #REF! | C26: =CONCATENATE(E26,R26) -> #REF! | D26: =CONCATENATE(E26,R26) -> #REF! | E26: =IF(G26=0,E24,G26) -> #REF! | F26: =IF(H26=0,F24,H26) -> #REF! | I26: TPAA103 | O26: 3457001 | P26: =+O26*1 -> 3457001 | Q26: =VLOOKUP(P26,[1]A!D:G,3,FALSE) -> C/F | R26: C/F 통합품 | S26: 0 | T26: 0 | U26: 0 | V26: 0 | W26: 0 | X26: 0 | Y26: 0 | Z26: 0 | AA26: 0 | AB26: 0 | AC26: 0 | AD26: 0 | AE26: 0 | AF26: 0 | AG26: 0 | AH26: 0 | AI26: 0 | AJ26: 0 | AK26: 0 | AL26: 0 | AM26: 0 | AN26: 0 | AO26: 0 | AP26: 0 | AQ26: 0 | AR26: 0 | AS26: 0 | AT26: 0 | AU26: 0 | AV26: 0 | AW26: 0 | AX26: 0 | AY26: 0 | AZ26: 0 | BA26: 0 | BB26: 0 | BC26: 0 | BD26: 0 | BE26: 0 | BF26: 0 | BG26: 0 | BH26: 0 | BI26: 0 | BJ26: 0 | BK26: 0 | BL26: 0 | BM26: 0 | BN26: 0 | BO26: 0 | BP26: 0 | BQ26: 0 | BR26: 0 | BS26: 0 | BT26: 0 | BU26: 0 | BV26: 0
B27: =CONCATENATE(E27,O27) -> #REF! | C27: =CONCATENATE(E27,R27) -> #REF! | D27: =CONCATENATE(E27,R27) -> #REF! | E27: =IF(G27=0,E25,G27) -> #REF! | F27: =IF(H27=0,F25,H27) -> #REF! | I27: TPAA103 | O27: 3457041 | P27: =+O27*1 -> 3457041 | Q27: =VLOOKUP(P27,[1]A!D:G,3,FALSE) -> C/F | R27: C/F KRC-U12(TEIJIN) | S27: 0.043343 | T27: 8602 | U27: 9497.51 | V27: 81697596 | W27: 0 | X27: 0 | Y27: 0 | Z27: 0 | AA27: 0 | AB27: 0 | AC27: 0 | AD27: 0 | AE27: 0 | AF27: 0 | AG27: 0 | AH27: 0 | AI27: 0.039618 | AJ27: 1307 | AK27: 9528.974 | AL27: 12454369 | AM27: 0.039796 | AN27: 2986 | AO27: 9450.0117 | AP27: 28217735 | AQ27: 0.04065 | AR27: 1849 | AS27: 9450.0119 | AT27: 17473072 | AU27: 0.04096 | AV27: 2509 | AW27: 9466.1989 | AX27: 23750693 | AY27: 0.039981 | AZ27: 995 | BA27: 9591.9075 | BB27: 9543948 | BC27: 0.039613 | BD27: 2082 | BE27: 9688.8372 | BF27: 20172159 | BG27: 0 | BH27: 0 | BI27: 0 | BJ27: 0 | BK27: 0.035845 | BL27: 2218 | BM27: 9625.2583 | BN27: 21348823 | BO27: 0.043227 | BP27: 3494 | BQ27: 9625.2582 | BR27: 33630652 | BS27: 0.040124 | BT27: 5420 | BU27: 10020.492 | BV27: 54311069
C28: =CONCATENATE(E28,R28) -> #REF! | E28: =IF(G28=0,E27,G28) -> #REF! | I28: TPAA103 | Q28: =VLOOKUP(P28,[1]A!D:G,3,FALSE) -> 0 | R28: =+Q27 -> C/F | S28: 0.04361 | T28: 8655 | U28: 9523.7299 | V28: 82427882 | W28: 0.04805 | X28: 2204 | Y28: 14373.57 | Z28: 31679348 | AA28: 0.050474 | AB28: 11251 | AC28: 14782.044 | AD28: 166312782 | AE28: 0 | AF28: 0 | AG28: 0 | AH28: 0 | AI28: 0.039618 | AJ28: 1307 | AK28: 9528.974 | AL28: 12454369 | AM28: 0.039796 | AN28: 2986 | AO28: 9450.0117 | AP28: 28217735 | AQ28: 0.04065 | AR28: 1849 | AS28: 9450.0119 | AT28: 17473072 | AU28: 0.04096 | AV28: 2509 | AW28: 9466.1989 | AX28: 23750693 | AY28: 0.039981 | AZ28: 995 | BA28: 9591.9075 | BB28: 9543948 | BC28: 0.039613 | BD28: 2082 | BE28: 9688.8372 | BF28: 20172159 | BG28: 0 | BH28: 0 | BI28: 0 | BJ28: 0 | BK28: 0.047481 | BL28: 2938 | BM28: 11177.655 | BN28: 32839951 | BO28: 0.043227 | BP28: 3494 | BQ28: 9625.2582 | BR28: 33630652 | BS28: 0.040124 | BT28: 5420 | BU28: 10020.492 | BV28: 54311069
B29: =CONCATENATE(E29,O29) -> #REF! | C29: =CONCATENATE(E29,R29) -> #REF! | D29: =CONCATENATE(E29,R29) -> #REF! | E29: =IF(G29=0,E28,G29) -> #REF! | F29: =IF(H29=0,F27,H29) -> #REF! | I29: TPAA103 | O29: 3459002 | P29: =+O29*1 -> 3459002 | Q29: =VLOOKUP(P29,[1]A!D:G,3,FALSE) -> G/F | R29: G/F KCC-CS311/395 | S29: 0 | T29: 0 | U29: 0 | V29: 0 | W29: 0.127864 | X29: 5865 | Y29: 1577.02 | Z29: 9249238 | AA29: 0.053453 | AB29: 11915 | AC29: 1596.6412 | AD29: 19023980 | AE29: 0 | AF29: 0 | AG29: 0 | AH29: 0 | AI29: 0.129069 | AJ29: 4258 | AK29: 1613.0669 | AL29: 6868439 | AM29: 0.103569 | AN29: 7771 | AO29: 1613.0669 | AP29: 12535143 | AQ29: 0.100844 | AR29: 4587 | AS29: 1613.0669 | AT29: 7399138 | AU29: 0.10564 | AV29: 6471 | AW29: 1613.0669 | AX29: 10438156 | AY29: 0.116205 | AZ29: 2892 | BA29: 1610.2113 | BB29: 4656731 | BC29: 0.108471 | BD29: 5701 | BE29: 1610.2112 | BF29: 9179814 | BG29: 0 | BH29: 0 | BI29: 0 | BJ29: 0 | BK29: 0.1065 | BL29: 6590 | BM29: 1608.0053 | BN29: 10596755 | BO29: 0.113646 | BP29: 9186 | BQ29: 1500 | BR29: 13779000 | BS29: 0.05265 | BT29: 7112 | BU29: 1469.2109 | BV29: 10449028
B30: =CONCATENATE(E30,O30) -> #REF! | C30: =CONCATENATE(E30,R30) -> #REF! | D30: =CONCATENATE(E30,R30) -> #REF! | E30: =IF(G30=0,E29,G30) -> #REF! | F30: =IF(H30=0,F27,H30) -> #REF! | I30: TPAA103 | O30: 3459011 | P30: =+O30*1 -> 3459011 | Q30: =VLOOKUP(P30,[1]A!D:G,3,FALSE) -> G/F | R30: T435N(태산) | S30: 0.125765 | T30: 24960 | U30: 1614.33 | V30: 40293559 | W30: 0 | X30: 0 | Y30: 0 | Z30: 0 | AA30: 0 | AB30: 0 | AC30: 0 | AD30: 0 | AE30: 0 | AF30: 0 | AG30: 0 | AH30: 0 | AI30: 0 | AJ30: 0 | AK30: 0 | AL30: 0 | AM30: 0 | AN30: 0 | AO30: 0 | AP30: 0 | AQ30: 0 | AR30: 0 | AS30: 0 | AT30: 0 | AU30: 0 | AV30: 0 | AW30: 0 | AX30: 0 | AY30: 0 | AZ30: 0 | BA30: 0 | BB30: 0 | BC30: 0 | BD30: 0 | BE30: 0 | BF30: 0 | BG30: 0 | BH30: 0 | BI30: 0 | BJ30: 0 | BK30: 0 | BL30: 0 | BM30: 0 | BN30: 0 | BO30: 0 | BP30: 0 | BQ30: 0 | BR30: 0 | BS30: 0.063665 | BT30: 8600 | BU30: 1455.4336 | BV30: 12516729
B31: =CONCATENATE(E31,O31) -> #REF! | C31: =CONCATENATE(E31,R31) -> #REF! | D31: =CONCATENATE(E31,R31) -> #REF! | E31: =IF(G31=0,E30,G31) -> #REF! | F31: =IF(H31=0,F27,H31) -> #REF! | I31: TPAA103 | O31: 3459012 | P31: =+O31*1 -> 3459012 | Q31: =VLOOKUP(P31,[1]A!D:G,3,FALSE) -> G/F | R31: G/F T436(태산) | S31: 0 | T31: 0 | U31: 0 | V31: 0 | W31: 0 | X31: 0 | Y31: 0 | Z31: 0 | AA31: 0 | AB31: 0 | AC31: 0 | AD31: 0 | AE31: 0 | AF31: 0 | AG31: 0 | AH31: 0 | AI31: 0 | AJ31: 0 | AK31: 0 | AL31: 0 | AM31: 0 | AN31: 0 | AO31: 0 | AP31: 0 | AQ31: 0 | AR31: 0 | AS31: 0 | AT31: 0 | AU31: 0 | AV31: 0 | AW31: 0 | AX31: 0 | AY31: 0 | AZ31: 0 | BA31: 0 | BB31: 0 | BC31: 0 | BD31: 0 | BE31: 0 | BF31: 0 | BG31: 0 | BH31: 0 | BI31: 0 | BJ31: 0 | BK31: 0 | BL31: 0 | BM31: 0 | BN31: 0 | BO31: 0 | BP31: 0 | BQ31: 0 | BR31: 0 | BS31: 0 | BT31: 0 | BU31: 0 | BV31: 0
B32: =CONCATENATE(E32,O32) -> #REF! | C32: =CONCATENATE(E32,R32) -> #REF! | D32: =CONCATENATE(E32,R32) -> #REF! | E32: =IF(G32=0,E31,G32) -> #REF! | F32: =IF(H32=0,F25,H32) -> #REF! | I32: TPAA103 | O32: 3459021 | P32: =+O32*1 -> 3459021 | Q32: =VLOOKUP(P32,[1]A!D:G,3,FALSE) -> G/F | R32: CS04-910 10P | S32: 0 | T32: 0 | U32: 0 | V32: 0 | W32: 0 | X32: 0 | Y32: 0 | Z32: 0 | AA32: 0 | AB32: 0 | AC32: 0 | AD32: 0 | AE32: 0 | AF32: 0 | AG32: 0 | AH32: 0 | AI32: 0 | AJ32: 0 | AK32: 0 | AL32: 0 | AM32: 0 | AN32: 0 | AO32: 0 | AP32: 0 | AQ32: 0 | AR32: 0 | AS32: 0 | AT32: 0 | AU32: 0 | AV32: 0 | AW32: 0 | AX32: 0 | AY32: 0 | AZ32: 0 | BA32: 0 | BB32: 0 | BC32: 0 | BD32: 0 | BE32: 0 | BF32: 0 | BG32: 0 | BH32: 0 | BI32: 0 | BJ32: 0 | BK32: 0 | BL32: 0 | BM32: 0 | BN32: 0 | BO32: 0 | BP32: 0 | BQ32: 0 | BR32: 0 | BS32: 0 | BT32: 0 | BU32: 0 | BV32: 0
B33: =CONCATENATE(E33,O33) -> #REF! | C33: =CONCATENATE(E33,R33) -> #REF! | D33: =CONCATENATE(E33,R33) -> #REF! | E33: =IF(G33=0,E32,G33) -> #REF! | F33: =IF(H33=0,F27,H33) -> #REF! | I33: TPAA103 | O33: 3459022 | P33: =+O33*1 -> 3459022 | Q33: =VLOOKUP(P33,[1]A!D:G,3,FALSE) -> G/F | R33: CS 995-10P | S33: 0 | T33: 0 | U33: 0 | V33: 0 | W33: 0 | X33: 0 | Y33: 0 | Z33: 0 | AA33: 0 | AB33: 0 | AC33: 0 | AD33: 0 | AE33: 0 | AF33: 0 | AG33: 0 | AH33: 0 | AI33: 0 | AJ33: 0 | AK33: 0 | AL33: 0 | AM33: 0 | AN33: 0 | AO33: 0 | AP33: 0 | AQ33: 0 | AR33: 0 | AS33: 0 | AT33: 0 | AU33: 0 | AV33: 0 | AW33: 0 | AX33: 0 | AY33: 0 | AZ33: 0 | BA33: 0 | BB33: 0 | BC33: 0 | BD33: 0 | BE33: 0 | BF33: 0 | BG33: 0 | BH33: 0 | BI33: 0 | BJ33: 0 | BK33: 0 | BL33: 0 | BM33: 0 | BN33: 0 | BO33: 0 | BP33: 0 | BQ33: 0 | BR33: 0 | BS33: 0 | BT33: 0 | BU33: 0 | BV33: 0
B34: =CONCATENATE(E34,O34) -> #REF! | C34: =CONCATENATE(E34,R34) -> #REF! | D34: =CONCATENATE(E34,R34) -> #REF! | E34: =IF(G34=0,E32,G34) -> #REF! | F34: =IF(H34=0,F33,H34) -> #REF! | I34: TPAA103 | O34: 3459029 | P34: =+O34*1 -> 3459029 | Q34: =VLOOKUP(P34,[1]A!D:G,3,FALSE) -> G/F | R34: G/F Changhai (중국) | S34: 0 | T34: 0 | U34: 0 | V34: 0 | W34: 0 | X34: 0 | Y34: 0 | Z34: 0 | AA34: 0.078809 | AB34: 17567 | AC34: 1639.1022 | AD34: 28794108 | AE34: 0 | AF34: 0 | AG34: 0 | AH34: 0 | AI34: 0 | AJ34: 0 | AK34: 0 | AL34: 0 | AM34: 0 | AN34: 0 | AO34: 0 | AP34: 0 | AQ34: 0 | AR34: 0 | AS34: 0 | AT34: 0 | AU34: 0 | AV34: 0 | AW34: 0 | AX34: 0 | AY34: 0 | AZ34: 0 | BA34: 0 | BB34: 0 | BC34: 0 | BD34: 0 | BE34: 0 | BF34: 0 | BG34: 0 | BH34: 0 | BI34: 0 | BJ34: 0 | BK34: 0 | BL34: 0 | BM34: 0 | BN34: 0 | BO34: 0 | BP34: 0 | BQ34: 0 | BR34: 0 | BS34: 0 | BT34: 0 | BU34: 0 | BV34: 0
B35: =CONCATENATE(E35,O35) -> #REF! | C35: =CONCATENATE(E35,R35) -> #REF! | D35: =CONCATENATE(E35,R35) -> #REF! | E35: =IF(G35=0,E32,G35) -> #REF! | F35: =IF(H35=0,F34,H35) -> #REF! | I35: TPAA103 | O35: 3459031 | P35: =+O35*1 -> 3459031 | Q35: =VLOOKUP(P35,[1]A!D:G,3,FALSE) -> G/F | R35: G/F HP3786 (대만) | S35: 0 | T35: 0 | U35: 0 | V35: 0 | W35: 0 | X35: 0 | Y35: 0 | Z35: 0 | AA35: 0 | AB35: 0 | AC35: 0 | AD35: 0 | AE35: 0 | AF35: 0 | AG35: 0 | AH35: 0 | AI35: 0 | AJ35: 0 | AK35: 0 | AL35: 0 | AM35: 0 | AN35: 0 | AO35: 0 | AP35: 0 | AQ35: 0 | AR35: 0 | AS35: 0 | AT35: 0 | AU35: 0 | AV35: 0 | AW35: 0 | AX35: 0 | AY35: 0 | AZ35: 0 | BA35: 0 | BB35: 0 | BC35: 0 | BD35: 0 | BE35: 0 | BF35: 0 | BG35: 0 | BH35: 0 | BI35: 0 | BJ35: 0 | BK35: 0 | BL35: 0 | BM35: 0 | BN35: 0 | BO35: 0 | BP35: 0 | BQ35: 0 | BR35: 0 | BS35: 0 | BT35: 0 | BU35: 0 | BV35: 0
B36: =CONCATENATE(E36,O36) -> #REF! | C36: =CONCATENATE(E36,R36) -> #REF! | D36: =CONCATENATE(E36,R36) -> #REF! | E36: =IF(G36=0,E33,G36) -> #REF! | F36: =IF(H36=0,F35,H36) -> #REF! | I36: TPAA103 | O36: 3459032 | P36: =+O36*1 -> 3459032 | Q36: =VLOOKUP(P36,[1]A!D:G,3,FALSE) -> G/F | R36: 국내G/F(NEG,OWENS,KCC) | S36: 0 | T36: 0 | U36: 0 | V36: 0 | W36: 0 | X36: 0 | Y36: 0 | Z36: 0 | AA36: 0 | AB36: 0 | AC36: 0 | AD36: 0 | AE36: 0 | AF36: 0 | AG36: 0 | AH36: 0 | AI36: 0 | AJ36: 0 | AK36: 0 | AL36: 0 | AM36: 0 | AN36: 0 | AO36: 0 | AP36: 0 | AQ36: 0 | AR36: 0 | AS36: 0 | AT36: 0 | AU36: 0 | AV36: 0 | AW36: 0 | AX36: 0 | AY36: 0 | AZ36: 0 | BA36: 0 | BB36: 0 | BC36: 0 | BD36: 0 | BE36: 0 | BF36: 0 | BG36: 0 | BH36: 0 | BI36: 0 | BJ36: 0 | BK36: 0 | BL36: 0 | BM36: 0 | BN36: 0 | BO36: 0 | BP36: 0 | BQ36: 0 | BR36: 0 | BS36: 0 | BT36: 0 | BU36: 0 | BV36: 0
C37: =CONCATENATE(E37,R37) -> #REF! | E37: =IF(G37=0,E36,G37) -> #REF! | I37: TPAA103 | Q37: =VLOOKUP(P37,[1]A!D:G,3,FALSE) -> 0 | R37: =+Q33 -> G/F | S37: 0.125765 | T37: 24960 | U37: 1614.3253 | V37: 40293559 | W37: 0.127864 | X37: 5865 | Y37: 1577.0227 | Z37: 9249238 | AA37: 0.132262 | AB37: 29482 | AC37: 1621.9418 | AD37: 47818088 | AE37: 0 | AF37: 0 | AG37: 0 | AH37: 0 | AI37: 0.129069 | AJ37: 4258 | AK37: 1613.0669 | AL37: 6868439 | AM37: 0.103569 | AN37: 7771 | AO37: 1613.0669 | AP37: 12535143 | AQ37: 0.100844 | AR37: 4587 | AS37: 1613.0669 | AT37: 7399138 | AU37: 0.10564 | AV37: 6471 | AW37: 1613.0669 | AX37: 10438156 | AY37: 0.116205 | AZ37: 2892 | BA37: 1610.2113 | BB37: 4656731 | BC37: 0.108471 | BD37: 5701 | BE37: 1610.2112 | BF37: 9179814 | BG37: 0 | BH37: 0 | BI37: 0 | BJ37: 0 | BK37: 0.1065 | BL37: 6590 | BM37: 1608.0053 | BN37: 10596755 | BO37: 0.113646 | BP37: 9186 | BQ37: 1500 | BR37: 13779000 | BS37: 0.116315 | BT37: 15712 | BU37: 1461.6699 | BV37: 22965757
B38: =CONCATENATE(E38,O38) -> 1103067 | C38: =CONCATENATE(E38,R38) -> 1103067생산투입 | D38: =CONCATENATE(E38,R38) -> 1103067생산투입 | E38: 1103067 | F38: =CONCATENATE(F29,R38) -> #REF! | I38: TPAA103 | P38: =+O38*1 -> 0 | Q38: =VLOOKUP(P38,[1]A!D:G,3,FALSE) -> 0 | R38: 생산투입 | S38: 1 | T38: 198465 | U38: 2487.8509 | V38: 493751334 | W38: 0.999999 | X38: 45869 | Y38: 2752.0013 | Z38: 126231549 | AA38: 0.999999 | AB38: 222907 | AC38: 2837.86 | AD38: 632578859 | AE38: 0 | AF38: 0 | AG38: 0 | AH38: 0 | AI38: 0.999999 | AJ38: 32990 | AK38: 2582.0114 | AL38: 85180556 | AM38: 0.999999 | AN38: 75032 | AO38: 2634.2984 | AP38: 197656680 | AQ38: 1 | AR38: 45486 | AS38: 2678.0301 | AT38: 121812877 | AU38: 0.999999 | AV38: 61255 | AW38: 2692.9251 | AX38: 164955127 | AY38: 1.000001 | AZ38: 24887 | BA38: 2702.6671 | BB38: 67261276 | BC38: 1.000001 | BD38: 52558 | BE38: 2727.6245 | BF38: 143358487 | BG38: 0 | BH38: 0 | BI38: 0 | BJ38: 0 | BK38: 1.000001 | BL38: 61878 | BM38: 2760.6958 | BN38: 170826335 | BO38: 1 | BP38: 80830 | BQ38: 2606.1547 | BR38: 210655481 | BS38: 1 | BT38: 135082 | BU38: 2531.8243 | BV38: 342003884
I39: TPAA103 | R39: 실사 재고 수량으로 조정 | AZ39: 1008 | BA39: 2521.8729 | BB39: 2542048
C40: =CONCATENATE(E40,R40) -> 1103067Loss | D40: =CONCATENATE(E40,R40) -> 1103067Loss | E40: =IF(G40=0,E38,G40) -> 1103067 | I40: TPAA103 | P40: =+O40*1 -> 0 | Q40: =VLOOKUP(P40,[1]A!D:G,3,FALSE) -> 0 | R40: Loss | S40: 0.017333031 | T40: 3440 | U40: 2487.8512 | V40: 8558208 | W40: 0.018269419 | X40: 838 | Y40: 2752.0012 | Z40: 2306177 | AA40: 0.01654053 | AB40: 3687 | AC40: 2837.8606 | AD40: 10463192 | AE40: 0 | AF40: 0 | AG40: 0 | AH40: 0 | AI40: 0.017399212 | AJ40: 574 | AK40: 2582.0105 | AL40: 1482074 | AM40: 0.017179337 | AN40: 1289 | AO40: 2634.2971 | AP40: 3395609 | AQ40: 0.01593897 | AR40: 725 | AS40: 2678.0303 | AT40: 1941572 | AU40: 0.016161946 | AV40: 990 | AW40: 2692.9253 | AX40: 2665996 | AY40: 0.016876281 | AZ40: 420 | BA40: 2702.6643 | BB40: 1135119 | BC40: 0.017142966 | BD40: 901 | BE40: 2727.6226 | BF40: 2457588 | BG40: 0 | BH40: 0 | BI40: 0 | BJ40: 0 | BK40: 0.016645658 | BL40: 1030 | BM40: 2760.6961 | BN40: 2843517 | BO40: 0.016454287 | BP40: 1330 | BQ40: 2606.1541 | BR40: 3466185 | BS40: 0.014302424 | BT40: 1932 | BU40: 2531.824 | BV40: 4891484
C41: =CONCATENATE(E41,R41) -> 1103067출고 | D41: =CONCATENATE(E41,R41) -> 1103067출고 | E41: =IF(G41=0,E40,G41) -> 1103067 | F41: TPAA103 | I41: TPAA103 | P41: =+O41*1 -> 0 | Q41: =VLOOKUP(P41,[1]A!D:G,3,FALSE) -> 0 | R41: 출고 | T41: 200000 | U41: 2497.8775 | V41: 499575502 | X41: 80000 | Y41: 2592.0208 | Z41: 207361668 | AB41: 200000 | AC41: 2798.6906 | AD41: 559738120 | AF41: 60000 | AG41: 2798.6906 | AH41: 167921436 | AJ41: 0 | AK41: 0 | AL41: 0 | AN41: 100000 | AO41: 2619.6278 | AP41: 261962785 | AR41: 0 | AS41: 0 | AT41: 0 | AV41: 20000 | AW41: 2682.4345 | AX41: 53648691 | AZ41: 40000 | BA41: 2685.2719 | BB41: 107410877 | BD41: 80000 | BE41: 2702.2205 | BF41: 216177640 | BH41: 0 | BI41: 0 | BJ41: 0 | BL41: 40000 | BM41: 2734.5866 | BN41: 109383465 | BP41: 80000 | BQ41: 2666.2594 | BR41: 213300753 | BT41: 40000 | BU41: 2577.9004 | BV41: 103116015
B42: =CONCATENATE(E38,D42) -> 11030671103067당월재고/단가 | C42: =CONCATENATE(E42,R42) -> 1103067당월재고/단가 | D42: =CONCATENATE(E42,R42) -> 1103067당월재고/단가 | E42: =IF(G42=0,E41,G42) -> 1103067 | I42: TPAA103 | P42: =+O42*1 -> 0 | Q42: =VLOOKUP(P42,[1]A!D:G,3,FALSE) -> 0 | R42: 당월재고/단가 | T42: 76517 | U42: 2497.8775 | V42: 191130094 | X42: 41548 | Y42: 2592.0333 | Z42: 107693798 | AB42: 60768 | AC42: 2798.6991 | AD42: 170071345 | AF42: 768 | AG42: 2799.3607 | AH42: 2149909 | AJ42: 33184 | AK42: 2587.0417 | AL42: 85848391 | AN42: 6927 | AO42: 2619.7022 | AP42: 18146677 | AR42: 51688 | AS42: 2670.2132 | AT42: 138017982 | AV42: 91953 | AW42: 2682.4402 | AX42: 246658422 | AZ42: 77428 | BA42: 2685.2786 | BB42: 207915750 | BD42: 49085 | BE42: 2702.231 | BF42: 132639009 | BH42: 49085 | BI42: 2702.231 | BJ42: 132639009 | BL42: 69933 | BM42: 2734.594 | BN42: 191238362 | BP42: 0 | BQ42: 0 | BR42: 0 | BT42: 0 | BU42: 0 | BV42: 0
...
